Workbook
Name 관할세무서: 세무서!$A$2:$A$115
Name 납부할세액: '1. 증여세신고서'!$X$25
Name 세대생략여부: 자료!$A$12:$A$14
Name 수증자선택: 자료!$A$2:$A$8
Name 예정신고여부: 자료!$A$17:$A$19
Name 증여공제액: 자료!$A$21:$B$33
Name 증여일: 증여내용입력!$C$18
Name 증여자와의관계: 자료!$A$22:$A$34
Name 증여재산: 자료!$A$37:$A$40

Sheet 증여내용입력
B1: * 아래의 칸에 정보를 입력하세요^^
B3: 수 증 자 | C3: 이름 | D3: 김자녀
C4: 주민번호 | D4: 1301111-3000000
C5: 거주구분 | D5: 거주자
C6: 주소 | D6: 서울시 강남구 OOO
C7: 전화번호 | D7: 010-0000-0000
C8: 증여자와관계 | D8: 배우자
B9: 관할 세무서 | D9: 삼성
B10: 세무서 코드/계좌번호 | D10: =VLOOKUP(D9,세무서!A2:C115,2,FALSE) -> 120 | E10: =VLOOKUP(D9,세무서!A2:C115,3,FALSE) -> 181149
B11: 증 여 자 | C11: 이름 | D11: 김부모
C12: 주민번호 | D12: 690211-1000000
C13: 주소 | D13: 서울시 000
C14: 전화번호 | D14: 010-0000-0000
B15: 세대생략여부 | D15: 예
B16: 예정신고여부 | D16: 예
B17: 현재 증여 재산 | C17: 증여일 | D17: 계좌번호 | E17: 금액 | F17: 재산종류 | M17: ▶ 증여세 상당액을 포함하여 증여할 경우 총증여 금액
C18: 45312 | E18: 50000000 | F18: 유가증권(비상장)
F19: <선택해주세요> | M19: 총 증여재산가액 (증여세 대납액 포함) | N19: =(N20+('1. 증여세신고서'!K23-SUM('1. 증여세신고서'!K25:N27))*'1. 증여세신고서'!K31*(1-'1. 증여세신고서'!AE21)-'1. 증여세신고서'!X18)/(1-'1. 증여세신고서'!K31*(1-'1. 증여세신고서'!AE21)) -> 50000000
F20: <선택해주세요> | M20: 당초증여재산가액 | N20: =증여내용입력!E22 -> 50000000
F21: <선택해주세요>
C22: 합계 | E22: =SUM(E18:E21) -> 50000000
B23: 기신고 증여분 | C23: 증여일 | D23: 계좌번호 | E23: 금액 | F23: 기납부세액
C26: 합계 | E26: =SUM(E24:E25) -> 0 | F26: =SUM(F24:F25) -> 0

Sheet 1. 증여세신고서
B2: ■ 상속세 및 증여세법 시행규칙 [별지 제10호서식] <개정 2020. 3. 13.>
B3: 증여세 과세표준신고 및 자진납부계산서
B4: 관리번호 | D4: ─ | I4: (기본세율 적용 증여재산 신고용)
B5: [ ]기한 내 신고 [ ]수정신고 [ ]기한 후 신고
AA6: (앞쪽)
B7: 수증자 | D7: 1. 성명 | G7: =증여내용입력!D3 -> 김자녀 | K7: 2. 주민등록번호 | O7: =증여내용입력!D4 -> 1301111-3000000 | T7: 3. 거주구분 | X7: =IF(증여내용입력!D5="거주자","[✔]","[ ]") -> [✔] | Y7: 거주자 | Z7: =IF(증여내용입력!D5="비거주자","[✔]","[ ]") -> [ ] | AA7: 비거주자
D8: 4. 주소 | G8: =증여내용입력!D6 -> 서울시 강남구 OOO | T8: 5. 전자우편주소
D9: 6. 전화번호 | G9: (자택) | N9: (휴대전화) | O9: =증여내용입력!D7 -> 010-0000-0000 | T9: 7. 증여자와의 관계 | X9: =증여내용입력!D8 -> 배우자
B10: 증여자 | D10: 8. 성명 | G10: =증여내용입력!D11 -> 김부모 | K10: 9. 주민등록번호 | O10: =증여내용입력!D12 -> 690211-1000000 | T10: 10. 증여일자 | X10: =증여내용입력!C18 -> 45312
D11: 11. 주소 | G11: =증여내용입력!D13 -> 서울시 000 | T11: 12. 전화번호 | X11: (자 택)
X12: (휴대전화) | Z12: =증여내용입력!D14 -> 010-0000-0000
B13: 세 무 대리인 | D13: 13. 성명 | K13: 14. 사업자등록번호 | T13: 15. 관리번호
D14: 16. 전화번호 | G14: (사무실) | O14: (휴대전화)
B16: 구 분 | K16: 금 액 | O16: 구 분 | X16: 금 액
B17: 17. | C17: 증여재산가액 | K17: =증여내용입력!E22 -> 50000000 | O17: 세액공제 | P17: 37. | Q17: 세액공제 합계 (38 + 39 + 40 + 41) | X17: =SUM(X18:AB21) -> 0
B18: 18. | C18: 비과세재산가액 | P18: 38. | Q18: 기납부세액 (「상속세 및 증여세법」 제58조) | X18: =증여내용입력!F26 -> 0
B19: 과 세 가 액 불산입 | D19: 19. | E19: 공익법인출연재산가액 (「상속세 및 증여세법」 제48조) | P19: 39. | Q19: 외국납부세액공제 (「상속세 및 증여세법」 제59조)
D20: 20. | E20: 공익신탁재산가액 (「상속세 및 증여세법」 제52조) | P20: 40. | Q20: 신고세액공제 (「상속세 및 증여세법」 제69조) | X20: =K34*VLOOKUP(증여내용입력!D16,자료!A17:B19,2,FALSE) -> 0
D21: 21. | E21: 장애인신탁재산가액 (「상속세 및 증여세법」 제52조의2) | P21: 41. | Q21: 그 밖의 공제ㆍ감면세액
B22: 22. | C22: 채무액 | O22: 42. | P22: 신고불성실가산세
B23: 23. | C23: 증여재산가산액 (「상속세 및 증여세법」 제47조제2항) | K23: =증여내용입력!E26 -> 0 | O23: 43. | P23: 납부지연가산세
B24: 24. | C24: 증 여 세 과 세 가 액 (17-18-19-20-21-22+23) | K24: =K17-K18-K19-K20-K21-K22+K23 -> 50000000 | O24: 44. | P24: 공익법인 등 관련 가산세 (「상속세 및 증여세법」 제78조)
B25: 증여재산공제 | D25: 25. | E25: 배 우 자 | K25: =IF(증여내용입력!D5="비거주자",0,IF(증여내용입력!D8="배우자",MIN(K24,VLOOKUP(증여내용입력!D8,증여공제액,2,FALSE)),0)) -> 50000000 | O25: 45. | P25: 자진납부할 세액(합계액) (34+35-36-37+42+43+44) | X25: =K34+K35-K36-X17+X22+X23+X24 -> 0
D26: 26. | E26: 직계존비속 | K26: =IF(OR(증여내용입력!D8="배우자",증여내용입력!D8="기타친족"),0,MIN(K24,VLOOKUP(증여내용입력!D8,증여공제액,2,FALSE))) -> 0 | O26: 납부방법 | T26: 납부및 신청일
D27: 27. | E27: 그 밖의 친족 | K27: =IF(증여내용입력!D5="비거주자",0,IF(증여내용입력!D8="기타친족",MIN(K24,VLOOKUP(증여내용입력!D8,증여공제액,2,FALSE)),0)) -> 0 | O27: 46. | P27: 연부연납
B28: 28. | C28: 재해손실공제 (「상속세 및 증여세법」 제54조) | O28: 현금 | P28: 47. | Q28: 분납
B29: 29. | C29: 감정평가수수료 | P29: 48. | Q29: 신고납부 | X29: =X25 -> 0
B30: 30. | C30: 과세표준(24-25-26-27-28-29) | K30: =K24-K25-K26-K27-K28-K29 -> 0 | O30: 「상속세 및 증여세법」 제68조 및 같은 법 시행령 제65조제1항에 따라 증여세의 과세가액 및 과세표준을 신고하며, 위 내용을 충분히 검토하였고 신고인이 알고 있는 사실을 그대로 적었음을 확인합니다.
B31: 31. | C31: 세율 | K31: =IF(K30<=500000, ,IF(K30>3000000000,50%,IF(K30>1000000000,40%,IF(K30>500000000,0.3,IF(K30>100000000,0.2,IF(K30>0,0.1,0)))))) -> 0
B32: 32. | C32: 산출세액 | K32: =ROUNDDOWN(IF(K30<500000,0,IF(K30<=100000000,K30*0.1,IF(K30<=500000000,K30*0.2-10000000,IF(K30<=1000000000,K30*0.3-60000000,IF(K30<=3000000000,K30*0.4-160000000,K30*0.5-460000000))))),-1) -> 0 | O32: =EOMONTH(증여일,3) -> 45412
B33: 33. | C33: 세대생략가산액 (「상속세및증여세법」 제57조) | K33: =K32*VLOOKUP(증여내용입력!D15,자료!A11:B14,2,FALSE) -> 0 | O33: 신고인 (서명 또는 인)
B34: 34. | C34: 산 출 세 액 계(32+33) | K34: =K32+K33 -> 0 | O34: 세무대리인은 조세전문자격자로서 위 신고서를 성실하고 공정하게 작성하였음을 확인합니다. 세무대리인 (서명 또는 인)
B35: 35. | C35: 이자상당액
B36: 36. | C36: 박물관자료 등 징수유예세액 | T36: 세무서장 귀하
B38: 신청(신고)인 제출서류 | F38: 1. 증여재산 및 평가명세서(부표) 1부 2. 채무사실 등 그 밖의 입증서류 1부 | Y38: 수수료 없음
B39: 담당공무원 확인사항 | F39: 1. 주민등록표등본 2. 증여자 및 수증자의 관계를 알 수 있는 가족관계등록부
B41: 행정정보 공동이용 동의서
B42: 본인은 이 건 업무처리와 관련하여 담당 공무원이 「전자정부법」 제36조제1항에 따른 행정정보의 공동이용을 통하여 위의 담당 공무원 확인 사항을 확인하는 것에 동의합니다. * 동의하지 아니하는 경우에는 신청인이 직접 관련 서류를 제출하여야 합니다
Q43: 신 청 인 | T43: =G7 -> 김자녀 | X43: (서명 또는 인)

Sheet 2. 평가명세서
B2: ■ 상속세 및 증여세법 시행규칙 [별지 제10호서식 부표] <개정 2022. 3. 18.>
J3: 증여재산 및 평가명세서
B4: 관리번호 | D4: ─
B6: 1. | C6: 재산구분 코 드 | D6: 2. | E6: 재산종류 코 드 | F6: 3. 소 재 지 ㆍ 법인명 등 | K6: 4. | L6: 사업자등록 번 호 ( 지 분 율 ) | M6: 5. | N6: 수 량 (면 적) | O6: 6. | P6: 단가 | Q6: 7. | R6: 평가 가액 | S6: 8. | T6: 평가기준 코 드
F7: 국외자산 여 부 | H7: 국외재산 국 가 명
B8: =VLOOKUP(증여내용입력!F18,자료!A36:D40,3,FALSE) -> A11 | D8: =VLOOKUP(증여내용입력!F18,자료!A42:D46,3,FALSE) -> 10 | F8: [ ]여 [ü]부 | I8: ㈜좋은회사 | K8: 001-000-0000 | M8: =Q8/O8 -> 2500 | O8: 20000 | Q8: =증여내용입력!E18 -> 50000000 | S8: =VLOOKUP(증여내용입력!F18,자료!A42:D46,4,FALSE) -> 08
B9: =VLOOKUP(증여내용입력!F19,자료!A36:D40,3,FALSE) -> 0 | D9: =VLOOKUP(증여내용입력!F19,자료!A42:D46,3,FALSE) -> 0 | F9: [ ]여 [ ]부 | S9: =VLOOKUP(증여내용입력!F19,자료!A42:D46,4,FALSE) -> 0
B10: =VLOOKUP(증여내용입력!F20,자료!A36:D40,3,FALSE) -> 0 | D10: =VLOOKUP(증여내용입력!F20,자료!A42:D46,3,FALSE) -> 0 | F10: [ ]여 [ ]부 | S10: =VLOOKUP(증여내용입력!F20,자료!A42:D46,4,FALSE) -> 0
B11: =VLOOKUP(증여내용입력!F21,자료!A36:D40,3,FALSE) -> 0 | D11: =VLOOKUP(증여내용입력!F21,자료!A42:D46,3,FALSE) -> 0 | F11: [ ]여 [ ]부 | S11: =VLOOKUP(증여내용입력!F21,자료!A42:D46,4,FALSE) -> 0
F12: [ ]여 [ ]부
F13: [ ]여 [ ]부
F14: [ ]여 [ ]부
F15: [ ]여 [ ]부
F16: [ ]여 [ ]부
F17: [ ]여 [ ]부
B19: 계 | D19: 9. | E19: 증여재산가액 | J19: ='1. 증여세신고서'!K17 -> 50000000
D20: 10. | E20: 비과세재산가액 | J20: ='1. 증여세신고서'!K18 -> 0
D21: 과세가액 불산입액 | F21: 11. | G21: 공익법인 출연재산가액 | J21: ='1. 증여세신고서'!K19 -> 0
F22: 12. | G22: 공익신탁 재산가액 | J22: ='1. 증여세신고서'!K20 -> 0
F23: 13. | G23: 장애인 신탁재산가액 | J23: ='1. 증여세신고서'!K21 -> 0
D24: 14. | E24: 증여재산가산액 | J24: ='1. 증여세신고서'!K23 -> 0
D25: 15. | E25: 합계 | J25: ='1. 증여세신고서'!K24 -> 50000000
B27: 첨부서류 | F27: 증여재산 증명서류 [예: 주주(증권계좌)번호 및 잔고증명서, 예금통장 사본 등] | S27: 수수료 없음

Sheet (참고) 2. 평가명세서 작성방법
B2: 작성방법
B3: A." 1. 재산구분코드"란 : 아래의 재산구분에 해당하는 코드를 적습니다.
B4: 재산구분 | C4: 증여재산 | D4: 증여재산 (영농농지) | E4: 증여재산가산 | F4: 비과세재산 (금양임야) | G4: 비과세재산 (문화재 등) | H4: 비과세재산 (기타) | I4: 과세가액불산입 (공익법인 출연재산) | J4: 과세가액불산입 (공익신탁 재산) | K4: 과세가액불산입 (장애인 신탁재산)
B6: 코드 | C6: A11 | D6: A14 | E6: A21 | F6: B11 | G6: B12 | H6: B13 | I6: B21 | J6: B22 | K6: B23
B8: B." 2. 재산종류코드"란 : 아래의 재산구분에 해당하는 코드를 적습니다.
B9: 재산구분 | C9: 현금 | D9: 토지Ⅰ (순수토지) | E9: 토지Ⅱ [일반건물(07)의 부수토지] | F9: 개별주택 (부수토지 포함) | G9: 공동주택 (부수토지 포함) | H9: 오피스텔ㆍ상업용건물 (부수토지 포함) | I9: 일반건물* (부수토지 제외) | J9: 부동산을 취득할 수 있는 권리 | K9: 유가증권 (상장) | L9: 유가증권 (비상장) | M9: 금융재산 (현금, 유가증권 제외) | N9: 기타재산 (01~11유형, 13유형 제외) | O9: 가상자산
B10: 코드 | C10: 1 | D10: 2 | E10: 3 | F10: 4 | G10: 5 | H10: 6 | I10: 7 | J10: 8 | K10: 9 | L10: 10 | M10: 11 | N10: 12 | O10: 13
B11: * 일반건물은 재산종류코드 04~06 유형을 제외한 건물을 말함
B12: C."3. 소재지ㆍ법인명 등"란 : 재산의 소재지 또는 법인명 등을 적습니다. 국외자산의 경우 국외자산여부에 ✔ 표시하고 해당 국가명을 별도 기재하고 소재지ㆍ법인명 등은 한글 또는 영문으로 적습니다. 부득이한 경우 해당 국가의 언어로 적습니다.
B13: 가. 소재지를 기재할 경우 : 해당 물건의 소재지번(예시 : 세종특별자치시 국세청로 8-14)을 적습니다.
B14: 나. 법인명 등을 기재할 경우 : 유가증권인 경우에는 해당 주식을 발행한 법인의 법인명을 적습니다. 그 외의 경우에는 재산명(예시 : 보험금인 경우 □□생명 △△보험 / 유가증권인 경우 ㈜○○건설)을 적습니다.
B15: D." 4. 사업자등록번호(지분율)"란 : " 재산종류"가 유가증권인 경우에는 해당 주식을 발행한 법인의 사업자등록번호를, 부동산인 경우에는 해당 수증자가 증여받은 부동산지분(예시: 증여자가 보유한 50% 지분 중 2분의 1을 수증자에게 증여하는 경우 25%로 기재)을 각각 적습니다.
B16: E."8.평가기준코드"란 : 아래의 평가기준에 해당하는 코드를 적습니다.
B17: 평가기준 | C17: 해당 재산의 매매거래가액 (「상속세 및 증여세법」 제60조) | D17: 해당 재산의 감정가액 (「상속세 및 증여세법」 제60조) | E17: 해당 재산의 수용보상가액 (「상속세 및 증여세법」 제60조) | F17: 해당 재산의 경매공매가액 (「상속세 및 증여세법」 제60조) | G17: 유사재산의 매매사례가액 등 (「상속세 및 증여세법」 제60조) | H17: 현금 등 가액 (「상속세 및 증여세법」 제60조) | I17: 저당권 등 평가특례가액 (「상속세 및 증여세법」 제66조) | J17: 기준시가 등 보충적 평가가액 (「상속세 및 증여세법」 제61조부터 제65조)
B18: 코드 | C18: 1 | D18: 2 | E18: 3 | F18: 4 | G18: 5 | H18: 6 | I18: 7 | J18: 8

Sheet 3. 납부서
B2: [별지 제8호서식]
B3: 영 수 필 통 지 서(징수기관용)
AQ4: (제1면)
B5: (전자) 납 부 번 호 | Y5: 수입징수관서 | AE5: 계 좌 번 호
B6: 분류기호 | G6: 서코드 | J6: 납부연월 | N6: 납부구분 | R6: 세목
B7: 0126 | G7: =증여내용입력!D10 -> 120 | J7: =AK14 -> 45412 | N7: 1 | R7: 33 | Y7: =증여내용입력!D9 -> 삼성 | AB7: 세무서 | AE7: =증여내용입력!E10 -> 181149
B8: 상 호(성명) | G8: =증여내용입력!D3 -> 김자녀 | L8: 사업자(주민)등록번호 | U8: =증여내용입력!D4 -> 1301111-3000000 | AE8: 일반회계 | AI8: 재정경제부소관 | AO8: 조세
B9: 사업장(주소) | G9: =증여내용입력!D6 -> 서울시 강남구 OOO | U9: 전화 | X9: =증여내용입력!D7 -> 010-0000-0000 | AE9: 회계연도 | AI9: =YEAR(AK14) -> 2024
B11: 귀속연도/기분 | H11: =YEAR(증여내용입력!C18) -> 2024 | L11: 년 귀속 | R11: 기 분 | V11: 왼쪽의 금액을 한국은행 국고(수납)대리점인 은행 또는 우체국에 납부하시기 바랍니다. (인터넷 등에 의한 전자납부 가능)
B12: 세 목 명 | H12: 납부금액
H13: 조 | I13: 천 | J13: 백 | K13: 십 | L13: 억 | M13: 천 | N13: 백 | O13: 십 | P13: 만 | Q13: 천 | R13: 백 | S13: 십 | T13: 원
B14: 증 여 세 | H14: =IF(납부할세액=0,"",IF(LEN(RIGHT(납부할세액,13))<13,"",MID(RIGHT(납부할세액,13),1,1))) | I14: =IF(납부할세액=0,"",IF(LEN(RIGHT(납부할세액,12))<12,"",MID(RIGHT(납부할세액,12),1,1))) | J14: =IF(납부할세액=0,"",IF(LEN(RIGHT(납부할세액,11))<11,"",MID(RIGHT(납부할세액,11),1,1))) | K14: =IF(납부할세액=0,"",IF(LEN(RIGHT(납부할세액,10))<10,"",MID(RIGHT(납부할세액,10),1,1))) | L14: =IF(납부할세액=0,"",IF(LEN(RIGHT(납부할세액,9))<9,"",MID(RIGHT(납부할세액,9),1,1))) | M14: =IF(납부할세액=0,"",IF(LEN(RIGHT(납부할세액,8))<8,"",MID(RIGHT(납부할세액,8),1,1))) | N14: =IF(납부할세액=0,"",IF(LEN(RIGHT(납부할세액,7))<7,"",MID(RIGHT(납부할세액,7),1,1))) | O14: =IF(납부할세액=0,"",IF(LEN(RIGHT(납부할세액,6))<6,"",MID(RIGHT(납부할세액,6),1,1))) | P14: =IF(납부할세액=0,"",IF(LEN(RIGHT(납부할세액,5))<5,"",MID(RIGHT(납부할세액,5),1,1))) | Q14: =IF(납부할세액=0,"",IF(LEN(RIGHT(납부할세액,4))<4,"",MID(RIGHT(납부할세액,4),1,1))) | R14: =IF(납부할세액=0,"",IF(LEN(RIGHT(납부할세액,3))<3,"",MID(RIGHT(납부할세액,3),1,1))) | S14: =IF(납부할세액=0,"",IF(LEN(RIGHT(납부할세액,2))<2,"",MID(RIGHT(납부할세액,2),1,1))) | T14: =IF(납부할세액=0,"",IF(LEN(RIGHT(납부할세액,1))<1,"",RIGHT(납부할세액,1))) | AG14: 납부기한 | AK14: =EOMONTH(증여일,3) -> 45412
U15: 년 월 일
AA16: 은 행 | AJ16: 지점 | AM16: 수납인
B17: 계 | H17: =H14 | I17: =I14 | J17: =J14 | K17: =K14 | L17: =L14 | M17: =M14 | N17: =N14 | O17: =O14 | ... T17: =T14 | AA17: 우체국
B18: 수납받을 때 납부자 실명번호인 "주민/사업자등록번호" 를 받드시 입력하여야 합니다.
B21: 납 부 서(수납기관용)
AQ22: (제2면)
B23: (전자) 납 부 번 호 | Y23: 수입징수관서 | AE23: =AE5 -> 계 좌 번 호
B24: 분류기호 | G24: 서코드 | J24: 납부연월 | N24: 납부구분 | R24: 세목
B25: =B7 -> 0126 | G25: =G7 -> 120 | J25: =J7 -> 45412 | N25: =N7 -> 1 | R25: =R7 -> 33 | Y25: =Y7 -> 삼성 | AB25: 세무서 | AE25: =AE7 -> 181149
B26: 상 호(성명) | G26: =G8 -> 김자녀 | L26: 사업자(주민)등록번호 | U26: =U8 -> 1301111-3000000 | AE26: 일반회계 | AI26: 재정경제부소관 | AO26: 조세
B27: 사업장(주소) | G27: =G9 -> 서울시 강남구 OOO | U27: 전화 | X27: =X9 -> 010-0000-0000 | AE27: 회계연도 | AI27: =AI9 -> 2024
B29: 귀속연도/기분 | H29: =H11 -> 2024 | L29: 년 귀속 | R29: 기 분 | V29: 왼쪽의 금액을 한국은행 국고(수납)대리점인 은행 또는 우체국에 납부하시기 바랍니다. (인터넷 등에 의한 전자납부 가능)
B30: 세 목 명 | H30: 납부금액
H31: 조 | I31: 천 | J31: 백 | K31: 십 | L31: 억 | M31: 천 | N31: 백 | O31: 십 | P31: 만 | Q31: 천 | R31: 백 | S31: 십 | T31: 원
B32: =B14 -> 증 여 세 | H32: =H14 | I32: =I14 | J32: =J14 | K32: =K14 | L32: =L14 | M32: =M14 | N32: =N14 | O32: =O14 | ... T32: =T14 | AG32: 납부기한 | AK32: =AK14 -> 45412
U33: 년 월 일
AA34: 은 행 | AJ34: 지점 | AM34: 수납인
B35: 계 | H35: =H32 | I35: =I32 | J35: =J32 | K35: =K32 | L35: =L32 | M35: =M32 | N35: =N32 | O35: =O32 | ... T35: =T32 | AA35: 우체국
B36: 수납받을 때 납부자 실명번호인 "주민/사업자등록번호" 를 받드시 입력하여야 합니다.
B39: 영 수 증 서(납세자용)
AQ40: (제3면)
B41: (전자) 납 부 번 호 | Y41: 수입징수관서 | AE41: =AE23 -> 계 좌 번 호
B42: 분류기호 | G42: 서코드 | J42: 납부연월 | N42: 납부구분 | R42: 세목
B43: =B25 -> 0126 | G43: =G25 -> 120 | J43: =J7 -> 45412 | N43: =N25 -> 1 | R43: =R25 -> 33 | Y43: =Y25 -> 삼성 | AB43: 세무서 | AE43: =AE25 -> 181149
B44: 상 호(성명) | G44: =G26 -> 김자녀 | L44: 사업자(주민)등록번호 | U44: =U26 -> 1301111-3000000 | AE44: 일반회계 | AI44: 재정경제부소관 | AO44: 조세
B45: 사업장(주소) | G45: =G27 -> 서울시 강남구 OOO | U45: 전화 | X45: =X9 -> 010-0000-0000 | AE45: 회계연도 | AI45: =AI27 -> 2024
B47: 귀속연도/기분 | H47: =H29 -> 2024 | L47: 년 귀속 | R47: 기 분 | V47: 왼쪽의 금액을 한국은행 국고(수납)대리점인 은행 또는 우체국에 납부하시기 바랍니다. (인터넷 등에 의한 전자납부 가능)
B48: 세 목 명 | H48: 납부금액
...

Sheet 세무서(가나다순)
A1: 세무서명 | B1: 지번 주소 | C1: 우편번호 | D1: 세무서코드 | E1: 계좌번호 | F1: 관할구역
A2: 강남 | B2: 서울특별시 강남구 청담동 45 | C2: 135951 | D2: 211 | E2: 180616 | F2: 강남구 중 신사동, 압구정동, 논현동, 청담동
A3: 강동 | B3: 서울특별시 송파구 풍납2동 388-6 | C3: 138750 | D3: 212 | E3: 180629 | F3: 강동구 전역
A4: 강릉 | B4: 강원도 강릉시 교동 산 68 | C4: 210921 | D4: 226 | E4: 150154 | F4: 강릉시. 평창군중 대관령면,진부면,용평면 및 정선군 중 임계면
A5: 강서 | B5: 서울특별시 영등포 양평4가 24 | C5: 150965 | D5: 109 | E5: 012027 | F5: 강서구 전체
A6: 거창 | B6: 경상남도 거창군 거창읍 상림리 80 | C6: 670807 | D6: 611 | E6: 950419 | F6: 경남 거창군, 함양군, 합천군
A7: 경산 | B7: 경상북도 경산시 사동 633-2 | C7: 712704 | D7: 515 | E7: 042330 | F7: 경산시, 청도군
A8: 경주 | B8: 경상북도 경주시 성동동 180-4 | C8: 780947 | D8: 505 | E8: 170176 | F8: 경주시, 영천시 전체
A9: 고양 | B9: 경기도 고양시 일산동구 장항동 774 | C9: 410741 | D9: 128 | E9: 012014 | F9: 고양시
A10: 공주 | B10: 충청남도 공주시 반죽동 18 | C10: 314800 | D10: 307 | E10: 080460 | F10: 충청남도 공주시 , 연기군
A11: 광주 | B11: 광주광역시 동구 호남동 39-1 | C11: 501120 | D11: 408 | E11: 060639 | F11: 광주광역시 동구,남구, 전남 화순군,곡성군
A12: 구로 | B12: 서울특별시 영등포구 문래1가 23-1 | C12: 150954 | D12: 113 | E12: 011756 | F12: 구로구 전체(신도림동등 19개동)
A13: 구미 | B13: 경상북도 구미시 공단동 174 | C13: 730902 | D13: 513 | E13: 905244 | F13: 경상북도 구미시, 칠곡군
... A110: 화성 | B110: 경기도 화성시 봉담읍 와우리 31-16 | C110: 445897 | D110: 143 | E110: 018351 | F110: 화성시 (기배동, 화산동, 진안동, 반월동, 병점1,2동, 동탄1,2,3동, 동탄면 제외)

Sheet 증여세계산(대납액)
B1: ☞ 당해 계산식은 증여를 받는 사람이 소득이 없거나 증여세를 납부할 재산이 없어 증여를 하는 사람이 증여와 동시에 증여세를 대신 납부해 주고자 할 때 증여세 대납액도 증여재 산가액에 포함하여 계산하기 위한 양식입니다.
B2: 증 여 세 계 산
B3: 구 분 | I3: 금 액
C4: 증여재산가액 | I4: =증여내용입력!E22 -> 50000000
B5: + | C5: 사전증여재산가액 | I5: =증여내용입력!E26 -> 0 | K5: 증여세차이
B6: + | C6: 증여세대납액 | K6: =I6-I16 -> 0
B7: = | C7: 증여세과세가액 | I7: =SUM(I4:J6) -> 50000000
B8: - | C8: 증여재산공제 | D8: =증여내용입력!D8 -> 배우자 | I8: =IF(VLOOKUP(D8,자료!A22:B34,2,FALSE)>I7,I7,VLOOKUP(D8,자료!A22:B34,2,FALSE)) -> 50000000 | O8: =IF(I7<I8,I7,I8) -> 50000000
B9: = | C9: 과세표준 | I9: =I7-O8 -> 0
B10: x | C10: 세율 | I10: =IF(I9<=500000, ,IF(I9>3000000000,50%,IF(I9>1000000000,40%,IF(I9>500000000,0.3,IF(I9>100000000,0.2,IF(I9>0,0.1,0)))))) -> 0
B11: = | C11: 산출세액 | I11: =ROUNDDOWN(IF(I9<500000,0,IF(I9<=100000000,I9*0.1,IF(I9<=500000000,I9*0.2-10000000,IF(I9<=1000000000,I9*0.3-60000000,IF(I9<=3000000000,I9*0.4-160000000,I9*0.5-460000000))))),-1) -> 0
B12: + | C12: 세대생략가산액 | I12: =VLOOKUP(증여내용입력!D15,자료!A12:B14,2,FALSE) -> 0.3 | J12: =I11*I12 -> 0
B13: = | C13: 산출세액계 | I13: =ROUNDDOWN(I11+J12,-1) -> 0
B14: - | C14: 기납부증여세액공제 | I14: =증여내용입력!F26 -> 0
B15: - | C15: 신고세액공제 | I15: =VLOOKUP(증여내용입력!D16,자료!A17:B19,2,FALSE) -> 0.03 | J15: =ROUNDDOWN((I13-I14)*I15,-1) -> 0
B16: = | C16: 납부할세액 | I16: =ROUNDDOWN(I13-J15-I14,-1) -> 0
B18: * 주의사항 : 증여재산가액은 금액으로 입력하고 분홍색으로 표식된 칸은 CASE에 맞게 선택하면 자동적으로 계산됩니다.
B21: * 증여세대납액의 경우 먼저 증여재산가액과 채무액을 입력하고 오른쪽에 붉은색으로 표시된 선택사항을 선택하여 증여세를 한번 계산한 후 마지막에 증여세차이(K6)를 0으로 만드는 목표값을 (데이터->가상분석->목표값찾기)에서 오른쪽 하단의 그림처럼 입력해서 찾으면 됩니다.

Sheet 세무서코드
A1: 세무서코드 및 계좌번호
A2: 세무서명 | B2: 세무서 코드 | C2: 계좌번호 | D2: 세무서명 | E2: 세무서 코드 | F2: 계좌번호 | G2: 세무서명 | H2: 세무서 코드 | I2: 계좌번호
A3: 강남 | B3: 211
A4: 강동 | B4: 212
A5: 강릉 | B5: 226
A6: 강서 | B6: 109
A7: 거창 | B7: 611
A8: 경산 | B8: 515
A9: 경주 | B9: 505
A10: 공주 | B10: 307
A11: 광주 | B11: 408
A12: 구로 | B12: 113
A13: 구미 | B13: 513
A14: 군산 | B14: 401
... A32: 동작 | B32: 108

Sheet 자료
A1: 수증자선택 | B1: 공제금액
A2: 배우자 | B2: 600000000
A3: 직계존속 | B3: 50000000
A4: 직계비속(미성년자 0) | B4: 20000000
A5: 직계비속(성인) | B5: 50000000
A6: 기타 친족 | B6: 10000000
A7: 기타 | B7: 0
A8: <선택해주세요>
A11: 세대생략여부 | B11: 가산액
A12: 예 | B12: 0.3 | C12: 2016. 1. 1. 이후 미성년자 손자 증여자산가액 20억원 초과하는 경우 40%
A13: 아니오 | B13: 0
A14: <선택해주세요>
A16: 예정신고여부 | B16: 공제액
A17: 예 | B17: 0.03
A18: 아니오 | B18: 0
A19: <선택해주세요>
A21: 증여자와의관계 | B21: 공제금액
A22: 조부 | B22: 50000000 | C22: 조부
A23: 조모 | B23: 50000000 | C23: 조모
A24: 부 | B24: 50000000 | C24: 부
A25: 모 | B25: 50000000 | C25: 모
A26: 배우자 | B26: 600000000 | C26: 배우자
A27: 자(미성년자) | B27: 20000000 | C27: 자
A28: 자(성인) | B28: 50000000 | C28: 자
A29: 자(성인, 혼인공제적용) | B29: 150000000
A30: 손자(미성년자) | B30: 20000000 | C30: 손자
A31: 손자(성인) | B31: 50000000 | C31: 손자
A32: 기타친족 | B32: 10000000 | C32: 기타친족
A33: 기타 | B33: 0 | C33: 기타
A34: <선택해주세요>
A36: 증여재산 | C36: 번호 | D36: 평가방법
A37: 현금 | B37: 현금 | C37: A11 | D37: 시가
A38: 유가증권(상장) | B38: 유가증권(상장) | C38: A11 | D38: 시가
A39: 유가증권(비상장) | B39: 유가증권(비상장) | C39: A11 | D39: 시가
A40: <선택해주세요>
A42: 증여재산 | C42: 번호 | D42: 평가방법
A43: 현금 | B43: 현금 | C43: 01 | D43: 06
A44: 유가증권(상장) | B44: 유가증권(상장) | C44: 09 | D44: 01
A45: 유가증권(비상장) | B45: 유가증권(비상장) | C45: 10 | D45: 08
A46: <선택해주세요>

Sheet 세무서
A1: 세무서명 | B1: 세무서코드 | C1: 계좌번호 | D1: 관할구역
A2: <선택해주세요> | B2: 세무서코드 | C2: 계좌번호
A3: 강남 | B3: 211 | C3: 180616 | D3: 강남구 중 신사동, 압구정동, 논현동, 청담동
A4: 강동 | B4: 212 | C4: 180629 | D4: 강동구 전역
A5: 강릉 | B5: 226 | C5: 150154 | D5: 강릉시. 평창군중 대관령면,진부면,용평면 및 정선군 중 임계면
A6: 강서 | B6: 109 | C6: 012027 | D6: 강서구 전체
A7: 거창 | B7: 611 | C7: 950419 | D7: 경남 거창군, 함양군, 합천군
A8: 경산 | B8: 515 | C8: 042330 | D8: 경산시, 청도군
A9: 경주 | B9: 505 | C9: 170176 | D9: 경주시, 영천시 전체
A10: 고양 | B10: 128 | C10: 012014 | D10: 고양시
A11: 공주 | B11: 307 | C11: 080460 | D11: 충청남도 공주시 , 연기군
A12: 광주 | B12: 408 | C12: 060639 | D12: 광주광역시 동구,남구, 전남 화순군,곡성군
A13: 구로 | B13: 113 | C13: 011756 | D13: 구로구 전체(신도림동등 19개동)
A14: 구미 | B14: 513 | C14: 905244 | D14: 경상북도 구미시, 칠곡군
... A111: 화성 | B111: 143 | C111: 018351 | D111: 화성시 (기배동, 화산동, 진안동, 반월동, 병점1,2동, 동탄1,2,3동, 동탄면 제외)
