Workbook
Name _v: #REF!
Name d_p: #REF!
Name h: #REF!
Name i: #REF!
Name i_평균: #REF!
Name ii: #REF!
Name j: #REF!
Name jong: #REF!
Name kR: #REF!
Name m: #REF!
Name mm: #REF!
Name n: #REF!
Name qr: #REF!
Name qw: #REF!
Name rate1: #REF!
Name rate1_LTC: #REF!
Name rate2: #REF!
Name rate2_LTC: #REF!
Name ri: #REF!
Name ro: #REF!
Name s: #REF!
Name s_table: #REF!
Name sex: #REF!
Name tb: #REF!
Name v: #REF!
Name v_평균: #REF!
Name vv: #REF!
Name WTF: #REF!
Name x: #REF!
Name α1: #REF!
Name α2: #REF!
Name β_: #REF!
Name β1: #REF!
Name β2: #REF!
Name γ: #REF!
Name ε1: #REF!
Name ε2: #REF!
Name ε2_: #REF!
Name ε2a: #REF!
Name ε2b: #REF!
Name 건강: #REF!

Sheet 계약기본사항
A1: ↓선택(필터 or 직접입력 or 우측항목복붙) | F1: (간편)더블보장 2504 버전 | J1: '주보험만시트로!!'
A2: 일반/간편 | B2: 일반가입 | D2: 일반가입 | E2: 간편가입 | J2: '주+특(기존)'시트로
A3: 암/간병 | B3: 암보장형 | D3: 암보장형 | E3: 암간병보장형 | J3: '주+특(생활비)'시트로!!
A4: 납기 | B4: 15년납 | C4: =SUBSTITUTE(B4,"년납",)-0 -> 15 | D4: 남자 | E4: 여자
A5: 가입금액 | B5: 50000 | D5: 15~75세(납기마다 상이)
A6: 환급특약 | B6: 보험료생활비환급특약P | C6: =IF(B6="특약 미가입",1,0) -> 0 | D6: 5년납 | E6: 7년납 | F6: 10년납 | G6: 15년납 | H6: 20년납 | I6: 30년납
A7: ↓가설과 비교 | D7: 1,000만~70,000(일반/간편 상이)
A8: 주보험료 | B8: 3330000 | D8: 특약 미가입 | E8: 보험료생활비환급특약P | F8: 보험료환급특약ⅢP [납입기간이후체감환급형] | H8: 1) 노란색음영만 수정(나머지는 미수정) 2) 값안바뀌면 상단 -> 계산옵션 -> '자동' 되있나 체크(수동이면 안됨)
A9: 환급특약 | B9: 343400 | D9: ←환급특약 가입금액 입력(미입력시 최대치 자동입력)
A10: 합계 | B10: =B8+B9 -> 3673400
A11: 총납입 | B11: =B10*C4*12 -> 661212000 | H11: =IF(B6=E8,"'주+특(생활비)'시트로!!",IF(B6=D8,"'주보험만시트로!!'","'주+특(기존)'시트로")) -> '주+특(생활비)'시트로!!
A12: ↓가설과 비교 | E12: ↓희망시점으로 변경가능
A13: 未진단시 주+특 해약환급금(년/만원/%) | C13: 환급률 | E13: 시점 | F13: 해지환급금 표시연수
A14: =F14&"년" -> 2년 | B14: 1808 | C14: 0.226 | E14: 납기중 예시 | F14: 2
A15: 완납 | B15: 59665 | C15: 0.995 | E15: 완납시점 | F15: =C4 -> 15
A16: =F16&"년" -> 20년 | B16: 62095 | C16: 1.035 | E16: 완납후 예시 | F16: =IF(OR(C4=5,C4=7),10,C4+5) -> 20
A18: 진단시 주보험 해약환급금(년/만원)
A19: =A14 -> 2년 | B19: 53067
A20: =A15 -> 완납 | B20: 67431
A21: =A16 -> 20년 | B21: 72444

Sheet 주보험만
AD5: 주보험만
AD26: 2504

Sheet 주+특(생활비) - 신규
AD5: 주+특(생활비) 신규
AD27: 2504

Sheet 주+특(기존)
AD4: 주+특(기존)
AD27: 2504

Sheet 자체계산시트
A1: =TEXT(C1,"#,###")&"원" -> 3,330,000원 | B1: 주보험료 | C1: =계약기본사항!B8 -> 3330000 | D1: =ROUNDDOWN(C1/10000,1) -> 333 | E1: =TEXT(D1,"#,###.#")&" 만원" -> 333. 만원 | F1: =C3*계약기본사항!C4*12 -> 661212000 | G1: 일반가입 | I1: 총납면 금액 | J1: =$C$1*(계약기본사항!C4-R8)*12 -> 519480000 | K1: =ROUNDDOWN((J1/10000),0) -> 51948 | L1: =TEXT(K1,"#,###")&" 만원" -> 51,948 만원 | M1: 주보험기납입 | N1: =계약기본사항!B8*계약기본사항!C4*12 -> 599400000 | O1: =ROUNDDOWN((N1/10000),0) -> 59940 | P1: =TEXT(O1,"#,###")&" 만원" -> 59,940 만원 | Q1: 주보험 생활비 암보장형 | R1: =ROUNDDOWN(($N$2/5)/10000,0) -> 11988 | S1: =TEXT(R1,"#,###")&" 만원" -> 11,988 만원 | T1: 보험료환급특약ⅢP [납입기간이후체감환급형] | AD1: 1000
A2: =TEXT(C2,"#,###")&"원" -> 343,400원 | B2: 특보험료 | C2: =계약기본사항!B9 -> 343400 | D2: =ROUNDDOWN(C2/10000,1) -> 34.3 | E2: =TEXT(D2,"#,###.#")&" 만원" -> 34.3 만원 | F2: =F1/10000 -> 66121.2 | G2: 간편가입 | K2: 주보납면액 | L2: ="("&A1&" x "&계약기본사항!C4-자체계산시트!R8&"년"&")" -> (3,330,000원 x 13년) | M2: 주보험암생활비 | N2: =N1 -> 599400000 | O2: =ROUNDDOWN((N2/10000),0) -> 59940 | P2: =TEXT(O2,"#,###")&" 만원" -> 59,940 만원 | Q2: 주보험 생활비 암간병보장형 | R2: =ROUNDDOWN(($N$2/10)/10000,0) -> 5994 | S2: =TEXT(R2,"#,###")&" 만원" -> 5,994 만원 | T2: 보험료생활비환급특약P | AD2: 1100
A3: =TEXT(C3,"#,###")&"원" -> 3,673,400원 | B3: 계약보험료 | C3: =계약기본사항!B10 -> 3673400 | D3: =ROUND(C3/10000,1) -> 367.3 | E3: =TEXT(D3,"#,###.#")&" 만원" -> 367.3 만원 | F3: =TEXT(F2,"#,###") -> 66,121 | G3: =IF(계약기본사항!B2=자체계산시트!$G$1,1,2) -> 1 | H3: =IF(G3=1,"더블보장보험","간편더블보장보험") -> 더블보장보험 | L3: ="("&A1&" x "&계약기본사항!C4-R8&"년"&")" -> (3,330,000원 x 13년) | M3: 페이백가입금액 | O3: =IF(계약기본사항!B9="","",IF(계약기본사항!C9="",+IF(계약기본사항!C6=1,"",MIN(ROUNDUP(계약기본사항!B8/10000,0),100)),계약기본사항!C9)) -> 100 | Q3: =IF(계약기본사항!B3=Q6,1,2) -> 1 | R3: =IF(Q3=1,"(암보장형)","(암간병보장형)") -> (암보장형) | T3: =IF(계약기본사항!B6=자체계산시트!$T$1,1,IF(계약기본사항!B6=자체계산시트!$T$2,2,0)) -> 2 | AD3: 1200
B4: 납기 | C4: =계약기본사항!C4 -> 15 | F4: ="("&E3&" x "&계약기본사항!C4&"년"&")" -> (367.3 만원 x 15년) | M4: 주보험가입금액 | O4: =계약기본사항!B5 -> 50000 | Q4: =IF(Q3=1,"5년","10년") -> 5년 | R4: =IF(Q3=1,R1,R2) -> 11988 | AD4: 1300
F5: ="("&A3&" x "&계약기본사항!C4&"년"&")" -> (3,673,400원 x 15년) | O5: =O4*2 -> 100000 | Q5: =IF(Q3=1,"최대 5년","최대 10년") -> 최대 5년 | AD5: 1400
Q6: 암보장형 | R6: 암간병보장형 | AD6: 1500
A7: 경과단위 | B7: 10 | D7: 미진단시 | Q7: 납기 | R7: 대납예시(연말) | T7: 주보험기납입 | W7: 총기납입 | AD7: 1600
C8: 2 | D8: 3 | E8: 4 | F8: 5 | G8: 6 | H8: 6 | I8: 7 | J8: 8 | Q8: 5 | R8: =계약기본사항!F14 -> 2 | S8: =IF(Q8-R8<=5,Q8-R8,5) -> 3 | T8: =R8*$C$1*12 -> 79920000 | U8: =T8/10000 -> 7992 | V8: =ROUNDDOWN(U8,1) -> 7992 | W8: =R8*$C$3*12 -> 88161600 | X8: =W8/10000 -> 8816.16 | Y8: =ROUNDDOWN(X8,1) -> 8816.1 | AD8: 1700
A9: 연말기준 | F9: 해약환급금 | G9: 환급률 | H9: 납입보험료 | I9: 사망보험금 | J9: 해약환급금 | K9: 실환급률 | L9: 페이백 일시금 | M9: 페이백분할 | Q9: 7 | R9: =계약기본사항!F15 -> 15 | S9: =IF(Q9-R9<=5,Q9-R9,5) -> -8 | T9: =R9*$C$1*12 -> 599400000 | U9: =T9/10000 -> 59940 | V9: =ROUNDDOWN(U9,1) -> 59940 | W9: =R9*$C$3*12 -> 661212000 | X9: =W9/10000 -> 66121.2 | Y9: =ROUNDDOWN(X9,1) -> 66121.2 | AD9: 1800
A10: =계약기본사항!F14 -> 2 | F10: =계약기본사항!B14 -> 1808 | G10: =계약기본사항!C14 -> 0.226 | J10: =계약기본사항!B19 -> 53067 | M10: =IF($T$3=0,"",IF($T$3=2,"",((MIN(5,A10+1-(VLOOKUP(#REF!,자체계산시트!$Q$7:$R$11,2,0))))*자체계산시트!$R$18))) | N10: =A10&"년" -> 2년 | Q10: 10 | R10: =계약기본사항!F16 -> 20 | S10: =IF(Q10-R10<=5,Q10-R10,5) -> -10 | T10: =R10*$C$1*12 -> 799200000 | U10: =T10/10000 -> 79920 | V10: =ROUNDDOWN(U10,1) -> 79920 | W10: =R10*$C$3*12 -> 881616000 | X10: =W10/10000 -> 88161.6 | Y10: =ROUNDDOWN(X10,1) -> 88161.6 | AD10: 1900
A11: =계약기본사항!F15 -> 15 | B11: 완납 | F11: =계약기본사항!B15 -> 59665 | G11: =계약기본사항!C15 -> 0.995 | J11: =계약기본사항!B20 -> 67431 | M11: =IF($T$3=0,"",IF($T$3=2,"",((MIN(5,A11+1-(VLOOKUP(#REF!,자체계산시트!$Q$7:$R$11,2,0))))*자체계산시트!$R$18))) | N11: =A11&"년" -> 15년 | Q11: 30 | R11: =계약기본사항!F16 -> 20 | S11: =IF(Q11-R11<=5,Q11-R11,5) -> 5 | T11: =R11*$C$1*12 -> 799200000 | U11: =T11/10000 -> 79920 | V11: =ROUNDDOWN(U11,1) -> 79920 | W11: =R11*$C$3*12 -> 881616000 | X11: =W11/10000 -> 88161.6 | Y11: =ROUNDDOWN(X11,1) -> 88161.6 | AD11: 2000
A12: =계약기본사항!F16 -> 20 | F12: =계약기본사항!B16 -> 62095 | G12: =계약기본사항!C16 -> 1.035 | J12: =계약기본사항!B21 -> 72444 | M12: =IF($T$3=0,"",IF($T$3=2,"",((MIN(5,A12+1-(VLOOKUP(#REF!,자체계산시트!$Q$7:$R$11,2,0))))*자체계산시트!$R$18))) | N12: =A12&"년" -> 20년 | Q12: 납입중 진단 기납입 보험료 | R12: =ROUNDDOWN(((C3*A10*12)/10000),0) -> 8816 | S12: =TEXT(R12,"#,###")&" 만원" -> 8,816 만원 | AD12: 2100
P13: 주보험 | Q13: 납기중 납면 | R13: =K1 -> 51948 | S13: =TEXT(R13,"#,###")&" 만원" -> 51,948 만원 | T13: =L3 -> (3,330,000원 x 13년) | AD13: 2200
P14: 페이백특약 | Q14: 납기중 환급 | R14: =IFERROR(IF(O3="-","",$O$3*R8*12),"") -> 2400 | S14: =TEXT(R14,"#,###")&" 만원" -> 2,400 만원 | T14: ="("&O3&" 만원"&" x "&R8&"년"&")" -> (100 만원 x 2년) | AD14: 2300
AD15: 2400
P16: 주보험 | Q16: 완납 후 생활비 | R16: =N1 -> 599400000 | S16: =P1 -> 59,940 만원 | T16: =IF($Q$3=1,"("&$S$1&" x "&$Q$5&")","("&$S$2&" x "&$Q$5&")") -> (11,988 만원 x 최대 5년) | Y16: =V1 -> 0 | AD16: 2500
P17: 페이백특약 | Q17: 완납 생활비(일시) | R17: =IFERROR(IF(O3="-","",$O$3*계약기본사항!C4*12*0.5),"") -> 9000 | S17: =TEXT(R17,"#,###")&" 만원" -> 9,000 만원 | T17: ="("&O3&" 만원"&" x "&계약기본사항!C4&"년"&" x 50%"&")" -> (100 만원 x 15년 x 50%) | AD17: 2600
P18: 페이백특약 | Q18: 완납 생활비(분할) | R18: =IFERROR(IF(T3=1,"",IF($O$3="-","",IF(Q3=1,$R$17/$W$18,R17/$W$18))),"") -> 1800 | S18: =TEXT(R18,"#,###")&" 만원" -> 1,800 만원 | T18: ="("&S18&" x "&"최대 "&W18&"년"&")" -> (1,800 만원 x 최대 5년) | V18: 횟수 | W18: =IF($Q$3=1,5,10) -> 5 | X18: =IFERROR(R18*W18,"") -> 9000 | AD18: 2700
AD19: 2800
AD20: 2900
Q21: 간병인 | R21: =IF(계약기본사항!B5<3000,10,60) -> 60 | AD21: 3000
Q22: 가사도우미 | R22: =R21*2 -> 120 | AD22: 3100
AD23: 3200
P24: 가입금액 | Q24: =계약기본사항!B5 -> 50000 | T24: =IF($Q$3=1,"("&$S$1&" x "&$Q$5&")","("&$S$2&" x "&$Q$5&")") -> (11,988 만원 x 최대 5년) | AD24: 3300
AD25: 3400
AD26: 3500
AD27: 3600
AD28: 3700
AD29: 3800
AD30: 3900
AD31: 4000
Q32: 일반가입 | R32: 암보장형 | S32: 남자 | T32: 5년납 | U32: 특약 미가입 | AD32: 4100
Q33: 간편가입 | R33: 암간병보장형 | S33: 여자 | T33: 7년납 | U33: 보험료생활비환급특약P | AD33: 4200
T34: 10년납 | U34: 보험료환급특약ⅢP [납입기간이후체감환급형] | AD34: 4300
T35: 15년납 | AD35: 4400
T36: 20년납 | AD36: 4500
T37: 30년납 | AD37: 4600
AD38: 4700
AD39: 4800
AD40: 4900
...
