Workbook
Name 고정연장근로: 임금대장수식!$X$2
Name 사업장: '정규직 월급제 포괄임금'!$AF$4
Name 최저시급: '정규직 월급제 포괄임금'!$F$16
Name 최저월급여환산액: '정규직 월급제 포괄임금'!$E$16

Sheet 정규직 월급제 포괄임금
B2: 임금대장 설계용 (2025년)
B4: 사업장 : A 주식회사 | P4: 상시근로자수 | R4: 5인 이상
U5: 조정안(최저임금 반영)
B6: 이름 | C6: 직급 | D6: 입사일 | E6: 월약정급여 | F6: 통상임금 * | G6: 임금시간 시수(H) | L6: 총임금 근로시간 | M6: 기본급여 + 연장수당 | Q6: 비과세 수당 | U6: 기본급여 + 연장수당 | Y6: 비과세 수당 | AC6: 최저임금적용 최소 월급여 (조정급여액) | AE6: 최저시급 | AF6: 10030
F7: (시간급) | G7: 기본근로 | H7: 주휴시수 | I7: 고정 연장근로(주간) | J7: 휴일근로(월간) | K7: 야간근로 또는 휴일연장근로(월간) | M7: 기본급 | N7: 고정 연장수당 | O7: 야간 또는 휴일근로(월간) | P7: 야간 또는 휴일연장근로(월간) | Q7: 식대 | R7: 차량유지비 | S7: 육아수당 | T7: 연구보조비 | U7: 기본급 | V7: 고정 연장수당 | W7: 야간 또는 휴일근로(월간) | X7: 야간 또는 휴일연장근로(월간) | Y7: 식대 | Z7: 차량유지비 | AA7: 육아수당 | AB7: 연구보조비 | AE7: (월환산액) | AF7: 2096270
B8: 이철수 | D8: 45658 | E8: 6000000 | F8: =IFERROR((E8)/L8,0) -> 23255.814 | G8: =IF(E8=0,0,ROUND((8*5)*(365/12/7),0)) -> 174 | H8: =IF(E8=0,0,ROUND(8*365/12/7,0)) -> 35 | I8: 5 | J8: 8 | K8: 2 | L8: =G8+H8+I9+J9+K9 -> 258 | M8: =IF(F8=0,0,F8*(G8+H8)-(Q8+R8+S8+T8)) -> 4260465.1 | N8: =F8*I9 -> 767441.86 | O8: =F8*J9 -> 279069.77 | P8: =F8*K9 -> 93023.256 | Q8: 200000 | R8: 200000 | S8: 200000 | U8: =IF(F8=0,0,MAX(최저월급여환산액-(Y8+Z8+AA8+AB8),F8*(G8+H8)-(Y8+Z8+AA8+AB8))) -> 4260465.1 | V8: =IF(U8<최저월급여환산액-(Y8+Z8+AA8+AB8-최저월급여환산액*1%),최저시급*I9,F8*I9) -> 767441.86 | W8: =F8*J9 -> 279069.77 | X8: =F8*K9 -> 93023.256 | Y8: =Q8 -> 200000 | Z8: =R8 -> 200000 | AA8: =S8 -> 200000 | AB8: =T8 -> 0 | AC8: =SUM(U8:AB9) -> 6000000
I9: =ROUND(I8*(365/12/7)*IF($R$4="5인 이상",1.5,1),0) -> 33 | J9: =ROUND(J8*IF($R$4="5인 이상",1.5,1),0) -> 12 | K9: =ROUND(K8*IF($R$4="5인 이상",1.5,1)+K8*IF($R$4="5인 이상",0.5,1),0) -> 4
B10: 홍길동 | D10: 45658 | E10: 2200000 | F10: =IFERROR((E10)/L10,0) -> 10526.316 | G10: =IF(E10=0,0,ROUND((8*5)*(365/12/7),0)) -> 174 | H10: =IF(E10=0,0,ROUND(8*365/12/7,0)) -> 35 | L10: =G10+H10+I11+J11+K11 -> 209 | M10: =IF(F10=0,0,F10*(G10+H10)-(Q10+R10+S10+T10)) -> 2000000 | N10: =F10*I11 -> 0 | O10: =F10*J11 -> 0 | P10: =F10*K11 -> 0 | Q10: 200000 | U10: =IF(F10=0,0,MAX(최저월급여환산액-(Y10+Z10+AA10+AB10),F10*(G10+H10)-(Y10+Z10+AA10+AB10))) -> 2000000 | V10: =IF(U10<최저월급여환산액-(Y10+Z10+AA10+AB10-최저월급여환산액*1%),최저시급*I11,F10*I11) -> 0 | W10: =F10*J11 -> 0 | X10: =F10*K11 -> 0 | Y10: =Q10 -> 200000 | Z10: =R10 -> 0 | AA10: =S10 -> 0 | AB10: =T10 -> 0 | AC10: =SUM(U10:AB11) -> 2200000
I11: =ROUND(I10*(365/12/7)*IF($R$4="5인 이상",1.5,1),0) -> 0 | J11: =ROUND(J10*IF($R$4="5인 이상",1.5,1),0) -> 0 | K11: =ROUND(K10*IF($R$4="5인 이상",1.5,1)+K10*IF($R$4="5인 이상",0.5,1),0) -> 0
F12: =IFERROR((E12)/L12,0) -> 0 | G12: =IF(E12=0,0,ROUND((8*5)*(365/12/7),0)) -> 0 | H12: =IF(E12=0,0,ROUND(8*365/12/7,0)) -> 0 | L12: =G12+H12+I13+J13+K13 -> 0 | M12: =IF(F12=0,0,F12*(G12+H12)-(Q12+R12+S12+T12)) -> 0 | N12: =F12*I13 -> 0 | O12: =F12*J13 -> 0 | P12: =F12*K13 -> 0 | U12: =IF(F12=0,0,MAX(최저월급여환산액-(Y12+Z12+AA12+AB12),F12*(G12+H12)-(Y12+Z12+AA12+AB12))) -> 0 | V12: =IF(U12<최저월급여환산액-(Y12+Z12+AA12+AB12-최저월급여환산액*1%),최저시급*I13,F12*I13) -> 0 | W12: =F12*J13 -> 0 | X12: =F12*K13 -> 0 | Y12: =Q12 -> 0 | Z12: =R12 -> 0 | AA12: =S12 -> 0 | AB12: =T12 -> 0 | AC12: =SUM(U12:AB13) -> 0
I13: =ROUND(I12*(365/12/7)*IF($R$4="5인 이상",1.5,1),0) -> 0 | J13: =ROUND(J12*IF($R$4="5인 이상",1.5,1),0) -> 0 | K13: =ROUND(K12*IF($R$4="5인 이상",1.5,1)+K12*IF($R$4="5인 이상",0.5,1),0) -> 0
F14: =IFERROR((E14)/L14,0) -> 0 | G14: =IF(E14=0,0,ROUND((8*5)*(365/12/7),0)) -> 0 | H14: =IF(E14=0,0,ROUND(8*365/12/7,0)) -> 0 | L14: =G14+H14+I15+J15+K15 -> 0 | M14: =IF(F14=0,0,F14*(G14+H14)-(Q14+R14+S14+T14)) -> 0 | N14: =F14*I15 -> 0 | O14: =F14*J15 -> 0 | P14: =F14*K15 -> 0 | U14: =IF(F14=0,0,MAX(최저월급여환산액-(Y14+Z14+AA14+AB14),F14*(G14+H14)-(Y14+Z14+AA14+AB14))) -> 0 | V14: =IF(U14<최저월급여환산액-(Y14+Z14+AA14+AB14-최저월급여환산액*1%),최저시급*I15,F14*I15) -> 0 | W14: =F14*J15 -> 0 | X14: =F14*K15 -> 0 | Y14: =Q14 -> 0 | Z14: =R14 -> 0 | AA14: =S14 -> 0 | AB14: =T14 -> 0 | AC14: =SUM(U14:AB15) -> 0
I15: =ROUND(I14*(365/12/7)*IF($R$4="5인 이상",1.5,1),0) -> 0 | J15: =ROUND(J14*IF($R$4="5인 이상",1.5,1),0) -> 0 | K15: =ROUND(K14*IF($R$4="5인 이상",1.5,1)+K14*IF($R$4="5인 이상",0.5,1),0) -> 0
B16: 2025년 최저임금 월급여액 | E16: =최저시급*209 -> 2096270 | F16: =AF6 -> 10030 | G16: =ROUND((8*5)*(365/12/7),0) -> 174 | H16: =ROUND(8*365/12/7,0) -> 35 | L16: =G16+H16+I17+J17+K17 -> 209 | M16: =IF(F16=0,0,F16*(G16+H16)-(Q16+R16+S16+T16)) -> 1896270 | N16: =F16*I17 -> 0 | O16: =F16*J17 -> 0 | P16: =F16*K17 -> 0 | Q16: 200000 | U16: =최저월급여환산액-(Y16+Z16+AA16+AB16) -> 1896270 | Y16: 200000 | AC16: =SUM(U16:AB17) -> 2096270
B18: 합계 | E18: =SUM(E8:E15) -> 8200000 | M18: =SUM(M8:M15) -> 6260465.1 | N18: =SUM(N8:N15) -> 767441.86 | O18: =SUM(O8:O15) -> 279069.77 | P18: =SUM(P8:P15) -> 93023.256 | Q18: =SUM(Q8:Q15) -> 400000 | R18: =SUM(R8:R15) -> 200000 | S18: =SUM(S8:S15) -> 200000 | T18: =SUM(T8:T15) -> 0 | ... AC18: =SUM(AC8:AC15) -> 8200000
B19: * 통상임금 붉은색은 최저시급에 미달인 경우
B20: * 노란색 셀에만 입력해 주세요.
B22: 임금의 구성
B23: 기본급 | C23: 소정근로시간 8시간 + 주휴수당 지급 | G23: - 소정근로시간에 대한 수당 지급 - 기본급과 비과세수당은 최저임금 이상이어야 함 - 월 209시간 기준 (실근로시간 174H + 주휴시수35H)
B24: 연장수당 | C24: 기본시간 초과 근무시 | G24: -일 8시간 초과, 주 40시간, 월 174시간 초과 근무는 연장근로 - 5인 이상 사업장 연장근무 1.5배 가산, 휴일근로(주휴일 근로) 1.5배 가산 - 야간근로(밤10시 ~ 오전6시) 0.5배 추가가산, 휴일 8시간 초과 연장근로 0.5배 추가 가산
B25: 비과세 수당 | C25: 비과세 급여 (월보수액에서 제외) | G25: - 식대(20만원), 차량유지비(20만원), 육아수당(20만원), 연구보조비(20만원), 생산직 연장·야간·휴일근로수당, 업무관련 학자금 등

Sheet 단시간근로자
B2: 단시간 근로자 임금대장 설계용
B3: 사업장 : OOO
B4: 고정 근로시간
B5: 이름 | C5: 직무 | D5: 입사일 | E5: 근로시간 (일간) | F5: 근로일수 (주당) | G5: 통상임금 (시간급) | H5: 임금시간 시수 | J5: 총임금 근로시간 | K5: 급여
H6: 기본근로 | I6: 주휴시수
B7: 홍길동 | C7: 파트타임 | D7: 45658 | E7: 5 | F7: 5 | G7: 10500 | H7: =ROUND((E7*F7)*(365/12/7),0) -> 109 | I7: =IF(ROUND(H7/(365/12/7)/5*365/12/7,0)<=12,0,ROUND(H7/(365/12/7)/5*365/12/7,0)) -> 22 | J7: =H7+I7 -> 131 | K7: =G7*J7 -> 1375500
B8: 2025년 최저임금 기준 지급 임금 | E8: =E7 -> 5 | F8: =F7 -> 5 | G8: =최저시급 -> 10030 | H8: =H7 -> 109 | I8: =I7 -> 22 | J8: =J7 -> 131 | K8: =J8*G8 -> 1313930
B9: * 주휴수당은 주(평균) 15시간 이상 근무시 적용함
B10: 변동 근로시간
B11: 이름 | C11: 직무 | D11: 입사일 | E11: 근로시간 (월간) | G11: 통상임금 (시간급) | H11: 임금시간 시수 | J11: 총임금 근로시간 | K11: 급여
H12: 기본근로 | I12: 주휴시수
B13: 홍길동 | C13: 아르바이트 | D13: 44929 | E13: 75 | G13: 10000 | H13: =E13 -> 75 | I13: =IF(ROUND(H13/(365/12/7)/5*365/12/7,0)<=12,0,ROUND(H13/(365/12/7)/5*365/12/7,0)) -> 15 | J13: =H13+I13 -> 90 | K13: =G13*J13 -> 900000
B14: 2025년 최저임금 기준 지급 임금 | E14: =E13 -> 75 | G14: =최저시급 -> 10030 | H14: =H13 -> 75 | I14: =I13 -> 15 | J14: =J13 -> 90 | K14: =J14*G14 -> 902700
B15: * 주휴수당은 주(평균) 15시간 이상 근무시 적용함

Sheet 임금대장 양식
B2: 임금대장 양식
B4: 사업장 : A 주식회사 | Q4: 상시근로자수 | S4: 5인 이상
V5: 조정안(최저임금 반영)
B6: 이름 | C6: 직급 | E6: 입사일 | F6: 월약정급여 | G6: 통상임금 * | H6: 임금시간 시수(H) | M6: 총임금 근로시간 | N6: 기본급여 + 연장수당 | R6: 비과세 수당 | V6: 기본급여 + 연장수당 | Z6: 비과세 수당 | AD6: 최저임금적용 최소 월급여 (조정급여액)
G7: (시간급) | H7: 기본근로 | I7: 주휴시수 | J7: 고정 연장근로(주간) | K7: 휴일근로(월간) | L7: 야간근로 또는 휴일연장근로(월간) | N7: 기본급 | O7: 고정 연장수당 | P7: 야간 또는 휴일근로(월간) | Q7: 야간 또는 휴일연장근로(월간) | R7: 식대 | S7: 차량유지비 | T7: 육아수당 | U7: 연구보조비 | V7: 기본급 | W7: 고정 연장수당 | X7: 야간 또는 휴일근로(월간) | Y7: 야간 또는 휴일연장근로(월간) | Z7: 식대 | AA7: 차량유지비 | AB7: 육아수당 | AC7: 연구보조비
B8: 이철수 | D8: =D7+1 -> 1 | E8: 45658 | F8: 4000000 | G8: =임금대장수식!G8 -> 15503.876 | H8: =임금대장수식!H8 -> 174 | I8: =임금대장수식!I8 -> 35 | J8: 5 | K8: 8 | L8: 2 | M8: =H8+I8+J9+K9+L9 -> 258 | N8: =임금대장수식!N8 -> 2640310.1 | O8: =임금대장수식!O8 -> 511627.91 | P8: =임금대장수식!P8 -> 186046.51 | Q8: =임금대장수식!Q8 -> 62015.504 | R8: 200000 | S8: 200000 | T8: 200000 | V8: =IF(G8=0,0,MAX(최저월급여환산액-(Z8+AA8+AB8+AC8),G8*(H8+I8)-(Z8+AA8+AB8+AC8))) -> 2640310.1 | W8: =IF(V8<최저월급여환산액-(Z8+AA8+AB8+AC8-최저월급여환산액*1%),최저시급*J9,G8*J9) -> 511627.91 | X8: =G8*K9 -> 186046.51 | Y8: =G8*L9 -> 62015.504 | Z8: =R8 -> 200000 | AA8: =S8 -> 200000 | AB8: =T8 -> 200000 | AC8: =U8 -> 0 | AD8: =SUM(V8:AC9) -> 4000000
J9: =임금대장수식!J9 -> 33 | K9: =임금대장수식!K9 -> 12 | L9: =임금대장수식!L9 -> 4
D10: =D8+1 -> 2 | G10: =임금대장수식!G10 -> 0 | H10: =임금대장수식!H10 -> 0 | I10: =임금대장수식!I10 -> 0 | M10: =H10+I10+J11+K11+L11 -> 0 | N10: =임금대장수식!N10 -> 0 | O10: =임금대장수식!O10 -> 0 | P10: =임금대장수식!P10 -> 0 | Q10: =임금대장수식!Q10 -> 0 | V10: =IF(G10=0,0,MAX(최저월급여환산액-(Z10+AA10+AB10+AC10),G10*(H10+I10)-(Z10+AA10+AB10+AC10))) -> 0 | W10: =IF(V10<최저월급여환산액-(Z10+AA10+AB10+AC10-최저월급여환산액*1%),최저시급*J11,G10*J11) -> 0 | X10: =G10*K11 -> 0 | Y10: =G10*L11 -> 0 | Z10: =R10 -> 0 | AA10: =S10 -> 0 | AB10: =T10 -> 0 | AC10: =U10 -> 0 | AD10: =SUM(V10:AC11) -> 0
J11: =임금대장수식!J11 -> 0 | K11: =임금대장수식!K11 -> 0 | L11: =임금대장수식!L11 -> 0
D12: =D10+1 -> 3 | G12: =임금대장수식!G12 -> 0 | H12: =임금대장수식!H12 -> 0 | I12: =임금대장수식!I12 -> 0 | M12: =H12+I12+J13+K13+L13 -> 0 | N12: =임금대장수식!N12 -> 0 | O12: =임금대장수식!O12 -> 0 | P12: =임금대장수식!P12 -> 0 | Q12: =임금대장수식!Q12 -> 0 | V12: =IF(G12=0,0,MAX(최저월급여환산액-(Z12+AA12+AB12+AC12),G12*(H12+I12)-(Z12+AA12+AB12+AC12))) -> 0 | W12: =IF(V12<최저월급여환산액-(Z12+AA12+AB12+AC12-최저월급여환산액*1%),최저시급*J13,G12*J13) -> 0 | X12: =G12*K13 -> 0 | Y12: =G12*L13 -> 0 | Z12: =R12 -> 0 | AA12: =S12 -> 0 | AB12: =T12 -> 0 | AC12: =U12 -> 0 | AD12: =SUM(V12:AC13) -> 0
J13: =임금대장수식!J13 -> 0 | K13: =임금대장수식!K13 -> 0 | L13: =임금대장수식!L13 -> 0
D14: =D12+1 -> 4 | G14: =임금대장수식!G14 -> 0 | H14: =임금대장수식!H14 -> 0 | I14: =임금대장수식!I14 -> 0 | M14: =H14+I14+J15+K15+L15 -> 0 | N14: =임금대장수식!N14 -> 0 | O14: =임금대장수식!O14 -> 0 | P14: =임금대장수식!P14 -> 0 | Q14: =임금대장수식!Q14 -> 0 | V14: =IF(G14=0,0,MAX(최저월급여환산액-(Z14+AA14+AB14+AC14),G14*(H14+I14)-(Z14+AA14+AB14+AC14))) -> 0 | W14: =IF(V14<최저월급여환산액-(Z14+AA14+AB14+AC14-최저월급여환산액*1%),최저시급*J15,G14*J15) -> 0 | X14: =G14*K15 -> 0 | Y14: =G14*L15 -> 0 | Z14: =R14 -> 0 | AA14: =S14 -> 0 | AB14: =T14 -> 0 | AC14: =U14 -> 0 | AD14: =SUM(V14:AC15) -> 0
J15: =임금대장수식!J15 -> 0 | K15: =임금대장수식!K15 -> 0 | L15: =임금대장수식!L15 -> 0

Sheet 임금대장수식
B2: 임금대장
B4: 사업장 : A 주식회사 | Q4: 상시근로자수 | S4: ='임금대장 양식'!S4 -> 5인 이상 | W4: 상시근로자수 | X4: ='정규직 월급제 포괄임금'!R4 -> 5인 이상
B6: 이름 | C6: 직급 | E6: 입사일 | F6: 월약정급여 | G6: 통상임금 * | H6: 임금시간 시수(H) | M6: 총임금 근로시간 | N6: 기본급여 + 연장수당 | R6: 비과세 수당 | W6: 최저시급 | X6: ='정규직 월급제 포괄임금'!AF6 -> 10030
G7: (시간급) | H7: 기본근로 | I7: 주휴시수 | J7: 고정 연장근로(주간) | K7: 휴일근로(월간) | L7: 야간근로 또는 휴일연장근로(월간) | N7: 기본급 | O7: 고정 연장수당 | P7: 야간 또는 휴일근로(월간) | Q7: 야간 또는 휴일연장근로(월간) | R7: 식대 | S7: 차량유지비 | T7: 육아수당 | U7: 연구보조비 | W7: (월환산액) | X7: ='정규직 월급제 포괄임금'!AF7 -> 2096270
B8: ='임금대장 양식'!B8 -> 이철수 | C8: {='임금대장 양식'!C8:C9} -> 0 | D8: ='임금대장 양식'!D8 -> 1 | E8: ='임금대장 양식'!E8 -> 45658 | F8: ='임금대장 양식'!F8 -> 4000000 | G8: =IFERROR((F8)/M8,0) -> 15503.876 | H8: =IF(F8=0,0,ROUND((8*5)*(365/12/7),0)) -> 174 | I8: =IF(F8=0,0,ROUND(8*365/12/7,0)) -> 35 | J8: ='임금대장 양식'!J8 -> 5 | K8: ='임금대장 양식'!K8 -> 8 | L8: ='임금대장 양식'!L8 -> 2 | M8: =H8+I8+J9+K9+L9 -> 258 | N8: =IF(G8=0,0,G8*(H8+I8)-(R8+S8+T8+U8)) -> 2640310.1 | O8: =G8*J9 -> 511627.91 | P8: =G8*K9 -> 186046.51 | Q8: =G8*L9 -> 62015.504 | R8: ='임금대장 양식'!R8 -> 200000 | S8: ='임금대장 양식'!S8 -> 200000 | T8: ='임금대장 양식'!T8 -> 200000 | U8: ='임금대장 양식'!U8 -> 0
C9: 0 | D9: ='임금대장 양식'!D9 -> 0 | J9: =ROUND(J8*(365/12/7)*IF($S$4="5인 이상",1.5,1),0) -> 33 | K9: =ROUND(K8*IF($S$4="5인 이상",1.5,1),0) -> 12 | L9: =ROUND(L8*IF($S$4="5인 이상",1.5,1)+L8*IF($S$4="5인 이상",0.5,1),0) -> 4
B10: ='임금대장 양식'!B10 -> 0 | C10: {='임금대장 양식'!C10:C11} -> 0 | D10: ='임금대장 양식'!D10 -> 2 | E10: ='임금대장 양식'!E10 -> 0 | F10: ='임금대장 양식'!F10 -> 0 | G10: =IFERROR((F10)/M10,0) -> 0 | H10: =IF(F10=0,0,ROUND((8*5)*(365/12/7),0)) -> 0 | I10: =IF(F10=0,0,ROUND(8*365/12/7,0)) -> 0 | J10: ='임금대장 양식'!J10 -> 0 | K10: ='임금대장 양식'!K10 -> 0 | L10: ='임금대장 양식'!L10 -> 0 | M10: =H10+I10+J11+K11+L11 -> 0 | N10: =IF(G10=0,0,G10*(H10+I10)-(R10+S10+T10+U10)) -> 0 | O10: =G10*J11 -> 0 | P10: =G10*K11 -> 0 | Q10: =G10*L11 -> 0 | R10: ='임금대장 양식'!R10 -> 0 | S10: ='임금대장 양식'!S10 -> 0 | T10: ='임금대장 양식'!T10 -> 0 | U10: ='임금대장 양식'!U10 -> 0
C11: 0 | D11: ='임금대장 양식'!D11 -> 0 | J11: =ROUND(J10*(365/12/7)*IF($S$4="5인 이상",1.5,1),0) -> 0 | K11: =ROUND(K10*IF($S$4="5인 이상",1.5,1),0) -> 0 | L11: =ROUND(L10*IF($S$4="5인 이상",1.5,1)+L10*IF($S$4="5인 이상",0.5,1),0) -> 0
B12: ='임금대장 양식'!B12 -> 0 | C12: {='임금대장 양식'!C12:C13} -> 0 | D12: ='임금대장 양식'!D12 -> 3 | E12: ='임금대장 양식'!E12 -> 0 | F12: ='임금대장 양식'!F12 -> 0 | G12: =IFERROR((F12)/M12,0) -> 0 | H12: =IF(F12=0,0,ROUND((8*5)*(365/12/7),0)) -> 0 | I12: =IF(F12=0,0,ROUND(8*365/12/7,0)) -> 0 | J12: ='임금대장 양식'!J12 -> 0 | K12: ='임금대장 양식'!K12 -> 0 | L12: ='임금대장 양식'!L12 -> 0 | M12: =H12+I12+J13+K13+L13 -> 0 | N12: =IF(G12=0,0,G12*(H12+I12)-(R12+S12+T12+U12)) -> 0 | O12: =G12*J13 -> 0 | P12: =G12*K13 -> 0 | Q12: =G12*L13 -> 0 | R12: ='임금대장 양식'!R12 -> 0 | S12: ='임금대장 양식'!S12 -> 0 | T12: ='임금대장 양식'!T12 -> 0 | U12: ='임금대장 양식'!U12 -> 0
C13: 0 | D13: ='임금대장 양식'!D13 -> 0 | J13: =ROUND(J12*(365/12/7)*IF($S$4="5인 이상",1.5,1),0) -> 0 | K13: =ROUND(K12*IF($S$4="5인 이상",1.5,1),0) -> 0 | L13: =ROUND(L12*IF($S$4="5인 이상",1.5,1)+L12*IF($S$4="5인 이상",0.5,1),0) -> 0
B14: ='임금대장 양식'!B14 -> 0 | C14: {='임금대장 양식'!C14:C15} -> 0 | D14: ='임금대장 양식'!D14 -> 4 | E14: ='임금대장 양식'!E14 -> 0 | F14: ='임금대장 양식'!F14 -> 0 | G14: =IFERROR((F14)/M14,0) -> 0 | H14: =IF(F14=0,0,ROUND((8*5)*(365/12/7),0)) -> 0 | I14: =IF(F14=0,0,ROUND(8*365/12/7,0)) -> 0 | J14: ='임금대장 양식'!J14 -> 0 | K14: ='임금대장 양식'!K14 -> 0 | L14: ='임금대장 양식'!L14 -> 0 | M14: =H14+I14+J15+K15+L15 -> 0 | N14: =IF(G14=0,0,G14*(H14+I14)-(R14+S14+T14+U14)) -> 0 | O14: =G14*J15 -> 0 | P14: =G14*K15 -> 0 | Q14: =G14*L15 -> 0 | R14: ='임금대장 양식'!R14 -> 0 | S14: ='임금대장 양식'!S14 -> 0 | T14: ='임금대장 양식'!T14 -> 0 | U14: ='임금대장 양식'!U14 -> 0
C15: 0 | D15: ='임금대장 양식'!D15 -> 0 | J15: =ROUND(J14*(365/12/7)*IF($S$4="5인 이상",1.5,1),0) -> 0 | K15: =ROUND(K14*IF($S$4="5인 이상",1.5,1),0) -> 0 | L15: =ROUND(L14*IF($S$4="5인 이상",1.5,1)+L14*IF($S$4="5인 이상",0.5,1),0) -> 0
B16: ='임금대장 양식'!B16 -> 0 | C16: {='임금대장 양식'!C16:C17} -> 0 | D16: ='임금대장 양식'!D16 -> 0 | E16: ='임금대장 양식'!E16 -> 0 | F16: ='임금대장 양식'!F16 -> 0 | G16: =IFERROR((F16)/M16,0) -> 0 | H16: =IF(F16=0,0,ROUND((8*5)*(365/12/7),0)) -> 0 | I16: =IF(F16=0,0,ROUND(8*365/12/7,0)) -> 0 | J16: ='임금대장 양식'!J16 -> 0 | K16: ='임금대장 양식'!K16 -> 0 | L16: ='임금대장 양식'!L16 -> 0 | M16: =H16+I16+J17+K17+L17 -> 0 | N16: =IF(G16=0,0,G16*(H16+I16)-(R16+S16+T16+U16)) -> 0 | O16: =G16*J17 -> 0 | P16: =G16*K17 -> 0 | Q16: =G16*L17 -> 0 | R16: ='임금대장 양식'!R16 -> 0 | S16: ='임금대장 양식'!S16 -> 0 | T16: ='임금대장 양식'!T16 -> 0 | U16: ='임금대장 양식'!U16 -> 0
C17: 0 | D17: ='임금대장 양식'!D17 -> 0 | J17: =ROUND(J16*(365/12/7)*IF($S$4="5인 이상",1.5,1),0) -> 0 | K17: =ROUND(K16*IF($S$4="5인 이상",1.5,1),0) -> 0 | L17: =ROUND(L16*IF($S$4="5인 이상",1.5,1)+L16*IF($S$4="5인 이상",0.5,1),0) -> 0
B18: ='임금대장 양식'!B18 -> 0 | C18: {='임금대장 양식'!C18:C19} -> 0 | D18: ='임금대장 양식'!D18 -> 0 | E18: ='임금대장 양식'!E18 -> 0 | F18: ='임금대장 양식'!F18 -> 0 | G18: =IFERROR((F18)/M18,0) -> 0 | H18: =IF(F18=0,0,ROUND((8*5)*(365/12/7),0)) -> 0 | I18: =IF(F18=0,0,ROUND(8*365/12/7,0)) -> 0 | J18: ='임금대장 양식'!J18 -> 0 | K18: ='임금대장 양식'!K18 -> 0 | L18: ='임금대장 양식'!L18 -> 0 | M18: =H18+I18+J19+K19+L19 -> 0 | N18: =IF(G18=0,0,G18*(H18+I18)-(R18+S18+T18+U18)) -> 0 | O18: =G18*J19 -> 0 | P18: =G18*K19 -> 0 | Q18: =G18*L19 -> 0 | R18: ='임금대장 양식'!R18 -> 0 | S18: ='임금대장 양식'!S18 -> 0 | T18: ='임금대장 양식'!T18 -> 0 | U18: ='임금대장 양식'!U18 -> 0
C19: 0 | D19: ='임금대장 양식'!D19 -> 0 | J19: =ROUND(J18*(365/12/7)*IF($S$4="5인 이상",1.5,1),0) -> 0 | K19: =ROUND(K18*IF($S$4="5인 이상",1.5,1),0) -> 0 | L19: =ROUND(L18*IF($S$4="5인 이상",1.5,1)+L18*IF($S$4="5인 이상",0.5,1),0) -> 0
B20: ='임금대장 양식'!B20 -> 0 | C20: {='임금대장 양식'!C20:C21} -> 0 | D20: ='임금대장 양식'!D20 -> 0 | E20: ='임금대장 양식'!E20 -> 0 | F20: ='임금대장 양식'!F20 -> 0 | G20: =IFERROR((F20)/M20,0) -> 0 | H20: =IF(F20=0,0,ROUND((8*5)*(365/12/7),0)) -> 0 | I20: =IF(F20=0,0,ROUND(8*365/12/7,0)) -> 0 | J20: ='임금대장 양식'!J20 -> 0 | K20: ='임금대장 양식'!K20 -> 0 | L20: ='임금대장 양식'!L20 -> 0 | M20: =H20+I20+J21+K21+L21 -> 0 | N20: =IF(G20=0,0,G20*(H20+I20)-(R20+S20+T20+U20)) -> 0 | O20: =G20*J21 -> 0 | P20: =G20*K21 -> 0 | Q20: =G20*L21 -> 0 | R20: ='임금대장 양식'!R20 -> 0 | S20: ='임금대장 양식'!S20 -> 0 | T20: ='임금대장 양식'!T20 -> 0 | U20: ='임금대장 양식'!U20 -> 0
C21: 0 | D21: ='임금대장 양식'!D21 -> 0 | J21: =ROUND(J20*(365/12/7)*IF($S$4="5인 이상",1.5,1),0) -> 0 | K21: =ROUND(K20*IF($S$4="5인 이상",1.5,1),0) -> 0 | L21: =ROUND(L20*IF($S$4="5인 이상",1.5,1)+L20*IF($S$4="5인 이상",0.5,1),0) -> 0
B22: ='임금대장 양식'!B22 -> 0 | C22: {='임금대장 양식'!C22:C23} -> 0 | D22: ='임금대장 양식'!D22 -> 0 | E22: ='임금대장 양식'!E22 -> 0 | F22: ='임금대장 양식'!F22 -> 0 | G22: =IFERROR((F22)/M22,0) -> 0 | H22: =IF(F22=0,0,ROUND((8*5)*(365/12/7),0)) -> 0 | I22: =IF(F22=0,0,ROUND(8*365/12/7,0)) -> 0 | J22: ='임금대장 양식'!J22 -> 0 | K22: ='임금대장 양식'!K22 -> 0 | L22: ='임금대장 양식'!L22 -> 0 | M22: =H22+I22+J23+K23+L23 -> 0 | N22: =IF(G22=0,0,G22*(H22+I22)-(R22+S22+T22+U22)) -> 0 | O22: =G22*J23 -> 0 | P22: =G22*K23 -> 0 | Q22: =G22*L23 -> 0 | R22: ='임금대장 양식'!R22 -> 0 | S22: ='임금대장 양식'!S22 -> 0 | T22: ='임금대장 양식'!T22 -> 0 | U22: ='임금대장 양식'!U22 -> 0
C23: 0 | D23: ='임금대장 양식'!D23 -> 0 | J23: =ROUND(J22*(365/12/7)*IF($S$4="5인 이상",1.5,1),0) -> 0 | K23: =ROUND(K22*IF($S$4="5인 이상",1.5,1),0) -> 0 | L23: =ROUND(L22*IF($S$4="5인 이상",1.5,1)+L22*IF($S$4="5인 이상",0.5,1),0) -> 0
B24: ='임금대장 양식'!B24 -> 0 | C24: {='임금대장 양식'!C24:C25} -> 0 | D24: ='임금대장 양식'!D24 -> 0 | E24: ='임금대장 양식'!E24 -> 0 | F24: ='임금대장 양식'!F24 -> 0 | G24: =IFERROR((F24)/M24,0) -> 0 | H24: =IF(F24=0,0,ROUND((8*5)*(365/12/7),0)) -> 0 | I24: =IF(F24=0,0,ROUND(8*365/12/7,0)) -> 0 | J24: ='임금대장 양식'!J24 -> 0 | K24: ='임금대장 양식'!K24 -> 0 | L24: ='임금대장 양식'!L24 -> 0 | M24: =H24+I24+J25+K25+L25 -> 0 | N24: =IF(G24=0,0,G24*(H24+I24)-(R24+S24+T24+U24)) -> 0 | O24: =G24*J25 -> 0 | P24: =G24*K25 -> 0 | Q24: =G24*L25 -> 0 | R24: ='임금대장 양식'!R24 -> 0 | S24: ='임금대장 양식'!S24 -> 0 | T24: ='임금대장 양식'!T24 -> 0 | U24: ='임금대장 양식'!U24 -> 0
C25: 0 | D25: ='임금대장 양식'!D25 -> 0 | J25: =ROUND(J24*(365/12/7)*IF($S$4="5인 이상",1.5,1),0) -> 0 | K25: =ROUND(K24*IF($S$4="5인 이상",1.5,1),0) -> 0 | L25: =ROUND(L24*IF($S$4="5인 이상",1.5,1)+L24*IF($S$4="5인 이상",0.5,1),0) -> 0
B26: ='임금대장 양식'!B26 -> 0 | C26: {='임금대장 양식'!C26:C27} -> 0 | D26: ='임금대장 양식'!D26 -> 0 | E26: ='임금대장 양식'!E26 -> 0 | F26: ='임금대장 양식'!F26 -> 0 | G26: =IFERROR((F26)/M26,0) -> 0 | H26: =IF(F26=0,0,ROUND((8*5)*(365/12/7),0)) -> 0 | I26: =IF(F26=0,0,ROUND(8*365/12/7,0)) -> 0 | J26: ='임금대장 양식'!J26 -> 0 | K26: ='임금대장 양식'!K26 -> 0 | L26: ='임금대장 양식'!L26 -> 0 | M26: =H26+I26+J27+K27+L27 -> 0 | N26: =IF(G26=0,0,G26*(H26+I26)-(R26+S26+T26+U26)) -> 0 | O26: =G26*J27 -> 0 | P26: =G26*K27 -> 0 | Q26: =G26*L27 -> 0 | R26: ='임금대장 양식'!R26 -> 0 | S26: ='임금대장 양식'!S26 -> 0 | T26: ='임금대장 양식'!T26 -> 0 | U26: ='임금대장 양식'!U26 -> 0
C27: 0 | D27: ='임금대장 양식'!D27 -> 0 | J27: =ROUND(J26*(365/12/7)*IF($S$4="5인 이상",1.5,1),0) -> 0 | K27: =ROUND(K26*IF($S$4="5인 이상",1.5,1),0) -> 0 | L27: =ROUND(L26*IF($S$4="5인 이상",1.5,1)+L26*IF($S$4="5인 이상",0.5,1),0) -> 0
B28: ='임금대장 양식'!B28 -> 0 | C28: {='임금대장 양식'!C28:C29} -> 0 | D28: ='임금대장 양식'!D28 -> 0 | E28: ='임금대장 양식'!E28 -> 0 | F28: ='임금대장 양식'!F28 -> 0 | G28: =IFERROR((F28)/M28,0) -> 0 | H28: =IF(F28=0,0,ROUND((8*5)*(365/12/7),0)) -> 0 | I28: =IF(F28=0,0,ROUND(8*365/12/7,0)) -> 0 | J28: ='임금대장 양식'!J28 -> 0 | K28: ='임금대장 양식'!K28 -> 0 | L28: ='임금대장 양식'!L28 -> 0 | M28: =H28+I28+J29+K29+L29 -> 0 | N28: =IF(G28=0,0,G28*(H28+I28)-(R28+S28+T28+U28)) -> 0 | O28: =G28*J29 -> 0 | P28: =G28*K29 -> 0 | Q28: =G28*L29 -> 0 | R28: ='임금대장 양식'!R28 -> 0 | S28: ='임금대장 양식'!S28 -> 0 | T28: ='임금대장 양식'!T28 -> 0 | U28: ='임금대장 양식'!U28 -> 0
C29: 0 | D29: ='임금대장 양식'!D29 -> 0 | J29: =ROUND(J28*(365/12/7)*IF($S$4="5인 이상",1.5,1),0) -> 0 | K29: =ROUND(K28*IF($S$4="5인 이상",1.5,1),0) -> 0 | L29: =ROUND(L28*IF($S$4="5인 이상",1.5,1)+L28*IF($S$4="5인 이상",0.5,1),0) -> 0
B30: ='임금대장 양식'!B30 -> 0 | C30: {='임금대장 양식'!C30:C31} -> 0 | D30: ='임금대장 양식'!D30 -> 0 | E30: ='임금대장 양식'!E30 -> 0 | F30: ='임금대장 양식'!F30 -> 0 | G30: =IFERROR((F30)/M30,0) -> 0 | H30: =IF(F30=0,0,ROUND((8*5)*(365/12/7),0)) -> 0 | I30: =IF(F30=0,0,ROUND(8*365/12/7,0)) -> 0 | J30: ='임금대장 양식'!J30 -> 0 | K30: ='임금대장 양식'!K30 -> 0 | L30: ='임금대장 양식'!L30 -> 0 | M30: =H30+I30+J31+K31+L31 -> 0 | N30: =IF(G30=0,0,G30*(H30+I30)-(R30+S30+T30+U30)) -> 0 | O30: =G30*J31 -> 0 | P30: =G30*K31 -> 0 | Q30: =G30*L31 -> 0 | R30: ='임금대장 양식'!R30 -> 0 | S30: ='임금대장 양식'!S30 -> 0 | T30: ='임금대장 양식'!T30 -> 0 | U30: ='임금대장 양식'!U30 -> 0
C31: 0 | D31: ='임금대장 양식'!D31 -> 0 | J31: =ROUND(J30*(365/12/7)*IF($S$4="5인 이상",1.5,1),0) -> 0 | K31: =ROUND(K30*IF($S$4="5인 이상",1.5,1),0) -> 0 | L31: =ROUND(L30*IF($S$4="5인 이상",1.5,1)+L30*IF($S$4="5인 이상",0.5,1),0) -> 0
B32: ='임금대장 양식'!B32 -> 0 | C32: {='임금대장 양식'!C32:C33} -> 0 | D32: ='임금대장 양식'!D32 -> 0 | E32: ='임금대장 양식'!E32 -> 0 | F32: ='임금대장 양식'!F32 -> 0 | G32: =IFERROR((F32)/M32,0) -> 0 | H32: =IF(F32=0,0,ROUND((8*5)*(365/12/7),0)) -> 0 | I32: =IF(F32=0,0,ROUND(8*365/12/7,0)) -> 0 | J32: ='임금대장 양식'!J32 -> 0 | K32: ='임금대장 양식'!K32 -> 0 | L32: ='임금대장 양식'!L32 -> 0 | M32: =H32+I32+J33+K33+L33 -> 0 | N32: =IF(G32=0,0,G32*(H32+I32)-(R32+S32+T32+U32)) -> 0 | O32: =G32*J33 -> 0 | P32: =G32*K33 -> 0 | Q32: =G32*L33 -> 0 | R32: ='임금대장 양식'!R32 -> 0 | S32: ='임금대장 양식'!S32 -> 0 | T32: ='임금대장 양식'!T32 -> 0 | U32: ='임금대장 양식'!U32 -> 0
C33: 0 | D33: ='임금대장 양식'!D33 -> 0 | J33: =ROUND(J32*(365/12/7)*IF($S$4="5인 이상",1.5,1),0) -> 0 | K33: =ROUND(K32*IF($S$4="5인 이상",1.5,1),0) -> 0 | L33: =ROUND(L32*IF($S$4="5인 이상",1.5,1)+L32*IF($S$4="5인 이상",0.5,1),0) -> 0
B34: ='임금대장 양식'!B34 -> 0 | C34: {='임금대장 양식'!C34:C35} -> 0 | D34: ='임금대장 양식'!D34 -> 0 | E34: ='임금대장 양식'!E34 -> 0 | F34: ='임금대장 양식'!F34 -> 0 | G34: =IFERROR((F34)/M34,0) -> 0 | H34: =IF(F34=0,0,ROUND((8*5)*(365/12/7),0)) -> 0 | I34: =IF(F34=0,0,ROUND(8*365/12/7,0)) -> 0 | J34: ='임금대장 양식'!J34 -> 0 | K34: ='임금대장 양식'!K34 -> 0 | L34: ='임금대장 양식'!L34 -> 0 | M34: =H34+I34+J35+K35+L35 -> 0 | N34: =IF(G34=0,0,G34*(H34+I34)-(R34+S34+T34+U34)) -> 0 | O34: =G34*J35 -> 0 | P34: =G34*K35 -> 0 | Q34: =G34*L35 -> 0 | R34: ='임금대장 양식'!R34 -> 0 | S34: ='임금대장 양식'!S34 -> 0 | T34: ='임금대장 양식'!T34 -> 0 | U34: ='임금대장 양식'!U34 -> 0
C35: 0 | D35: ='임금대장 양식'!D35 -> 0 | J35: =ROUND(J34*(365/12/7)*IF($S$4="5인 이상",1.5,1),0) -> 0 | K35: =ROUND(K34*IF($S$4="5인 이상",1.5,1),0) -> 0 | L35: =ROUND(L34*IF($S$4="5인 이상",1.5,1)+L34*IF($S$4="5인 이상",0.5,1),0) -> 0
B36: ='임금대장 양식'!B36 -> 0 | C36: {='임금대장 양식'!C36:C37} -> 0 | D36: ='임금대장 양식'!D36 -> 0 | E36: ='임금대장 양식'!E36 -> 0 | F36: ='임금대장 양식'!F36 -> 0 | G36: =IFERROR((F36)/M36,0) -> 0 | H36: =IF(F36=0,0,ROUND((8*5)*(365/12/7),0)) -> 0 | I36: =IF(F36=0,0,ROUND(8*365/12/7,0)) -> 0 | J36: ='임금대장 양식'!J36 -> 0 | K36: ='임금대장 양식'!K36 -> 0 | L36: ='임금대장 양식'!L36 -> 0 | M36: =H36+I36+J37+K37+L37 -> 0 | N36: =IF(G36=0,0,G36*(H36+I36)-(R36+S36+T36+U36)) -> 0 | O36: =G36*J37 -> 0 | P36: =G36*K37 -> 0 | Q36: =G36*L37 -> 0 | R36: ='임금대장 양식'!R36 -> 0 | S36: ='임금대장 양식'!S36 -> 0 | T36: ='임금대장 양식'!T36 -> 0 | U36: ='임금대장 양식'!U36 -> 0
C37: 0 | D37: ='임금대장 양식'!D37 -> 0 | J37: =ROUND(J36*(365/12/7)*IF($S$4="5인 이상",1.5,1),0) -> 0 | K37: =ROUND(K36*IF($S$4="5인 이상",1.5,1),0) -> 0 | L37: =ROUND(L36*IF($S$4="5인 이상",1.5,1)+L36*IF($S$4="5인 이상",0.5,1),0) -> 0
B38: ='임금대장 양식'!B38 -> 0 | C38: {='임금대장 양식'!C38:C39} -> 0 | D38: ='임금대장 양식'!D38 -> 0 | E38: ='임금대장 양식'!E38 -> 0 | F38: ='임금대장 양식'!F38 -> 0 | G38: =IFERROR((F38)/M38,0) -> 0 | H38: =IF(F38=0,0,ROUND((8*5)*(365/12/7),0)) -> 0 | I38: =IF(F38=0,0,ROUND(8*365/12/7,0)) -> 0 | J38: ='임금대장 양식'!J38 -> 0 | K38: ='임금대장 양식'!K38 -> 0 | L38: ='임금대장 양식'!L38 -> 0 | M38: =H38+I38+J39+K39+L39 -> 0 | N38: =IF(G38=0,0,G38*(H38+I38)-(R38+S38+T38+U38)) -> 0 | O38: =G38*J39 -> 0 | P38: =G38*K39 -> 0 | Q38: =G38*L39 -> 0 | R38: ='임금대장 양식'!R38 -> 0 | S38: ='임금대장 양식'!S38 -> 0 | T38: ='임금대장 양식'!T38 -> 0 | U38: ='임금대장 양식'!U38 -> 0
C39: 0 | D39: ='임금대장 양식'!D39 -> 0 | J39: =ROUND(J38*(365/12/7)*IF($S$4="5인 이상",1.5,1),0) -> 0 | K39: =ROUND(K38*IF($S$4="5인 이상",1.5,1),0) -> 0 | L39: =ROUND(L38*IF($S$4="5인 이상",1.5,1)+L38*IF($S$4="5인 이상",0.5,1),0) -> 0
B40: ='임금대장 양식'!B40 -> 0 | C40: {='임금대장 양식'!C40:C41} -> 0 | D40: ='임금대장 양식'!D40 -> 0 | E40: ='임금대장 양식'!E40 -> 0 | F40: ='임금대장 양식'!F40 -> 0 | G40: =IFERROR((F40)/M40,0) -> 0 | H40: =IF(F40=0,0,ROUND((8*5)*(365/12/7),0)) -> 0 | I40: =IF(F40=0,0,ROUND(8*365/12/7,0)) -> 0 | J40: ='임금대장 양식'!J40 -> 0 | K40: ='임금대장 양식'!K40 -> 0 | L40: ='임금대장 양식'!L40 -> 0 | M40: =H40+I40+J41+K41+L41 -> 0 | N40: =IF(G40=0,0,G40*(H40+I40)-(R40+S40+T40+U40)) -> 0 | O40: =G40*J41 -> 0 | P40: =G40*K41 -> 0 | Q40: =G40*L41 -> 0 | R40: ='임금대장 양식'!R40 -> 0 | S40: ='임금대장 양식'!S40 -> 0 | T40: ='임금대장 양식'!T40 -> 0 | U40: ='임금대장 양식'!U40 -> 0
C41: 0 | D41: ='임금대장 양식'!D41 -> 0 | J41: =ROUND(J40*(365/12/7)*IF($S$4="5인 이상",1.5,1),0) -> 0 | K41: =ROUND(K40*IF($S$4="5인 이상",1.5,1),0) -> 0 | L41: =ROUND(L40*IF($S$4="5인 이상",1.5,1)+L40*IF($S$4="5인 이상",0.5,1),0) -> 0
B42: ='임금대장 양식'!B42 -> 0 | C42: {='임금대장 양식'!C42:C43} -> 0 | D42: ='임금대장 양식'!D42 -> 0 | E42: ='임금대장 양식'!E42 -> 0 | F42: ='임금대장 양식'!F42 -> 0 | G42: =IFERROR((F42)/M42,0) -> 0 | H42: =IF(F42=0,0,ROUND((8*5)*(365/12/7),0)) -> 0 | I42: =IF(F42=0,0,ROUND(8*365/12/7,0)) -> 0 | J42: ='임금대장 양식'!J42 -> 0 | K42: ='임금대장 양식'!K42 -> 0 | L42: ='임금대장 양식'!L42 -> 0 | M42: =H42+I42+J43+K43+L43 -> 0 | N42: =IF(G42=0,0,G42*(H42+I42)-(R42+S42+T42+U42)) -> 0 | O42: =G42*J43 -> 0 | P42: =G42*K43 -> 0 | Q42: =G42*L43 -> 0 | R42: ='임금대장 양식'!R42 -> 0 | S42: ='임금대장 양식'!S42 -> 0 | T42: ='임금대장 양식'!T42 -> 0 | U42: ='임금대장 양식'!U42 -> 0
C43: 0 | D43: ='임금대장 양식'!D43 -> 0 | J43: =ROUND(J42*(365/12/7)*IF($S$4="5인 이상",1.5,1),0) -> 0 | K43: =ROUND(K42*IF($S$4="5인 이상",1.5,1),0) -> 0 | L43: =ROUND(L42*IF($S$4="5인 이상",1.5,1)+L42*IF($S$4="5인 이상",0.5,1),0) -> 0
...
